Workbook

Sheet Raw Data
A1: BRAND | B1: PesaPal Kenya | D1: PERIOD | E1: 1 Jan 2025 – 31 Mar 2025 (90 days) | G1: ANALYST | H1: TECKLER NDIANY
A2: Date | B2: Week | C2: Platform | D2: Content Type | E2: Post Topic | F2: Reach | G2: Impressions | H2: Likes | I2: Comments | J2: Shares | K2: Saves | L2: Profile Visits | M2: Link Clicks | N2: New Followers | O2: Engagement Rate (%) | P2: Notes
A3: 01-Jan-2025 | B3: W01 | C3: Instagram | D3: Promotional | E3: Refer a friend get KSh 100 | F3: 921 | G3: 1060 | H3: 10 | I3: 2 | J3: 0 | K3: 0 | L3: 53 | M3: 36 | N3: 7 | O3: 1.8
A4: 01-Jan-2025 | B4: W01 | C4: Facebook | D4: Community / Cultural | E4: End of financial year, our journey | F4: 3226 | G4: 3904 | H4: 42 | I4: 5 | J4: 6 | K4: 7 | L4: 216 | M4: 57 | N4: 15 | O4: 1.96
A5: 02-Jan-2025 | B5: W01 | C5: Instagram | D5: Educational | E5: 5 ways to save with mobile money | F5: 4247 | G5: 6385 | H5: 95 | I5: 26 | J5: 11 | K5: 15 | L5: 451 | M5: 173 | N5: 22 | O5: 3.57
A6: 02-Jan-2025 | B6: W01 | C6: TikTok | D6: Product Feature | E6: International transfers, step by step | F6: 1916 | G6: 2741 | H6: 82 | I6: 19 | J6: 13 | K6: 10 | L6: 146 | M6: 99 | N6: 12 | O6: 6.16
A7: 03-Jan-2025 | B7: W01 | C7: Facebook | D7: Behind the Scenes | E7: PesaPal turns 5, the early days | F7: 1021 | G7: 1447 | H7: 8 | I7: 1 | J7: 1 | K7: 2 | L7: 97 | M7: 21 | N7: 5 | O7: 1.49
A8: 03-Jan-2025 | B8: W01 | C8: LinkedIn | D8: Community / Cultural | E8: #NjaaaKwetuChallenge, save together | F8: 1029 | G8: 1148 | H8: 20 | I8: 3 | J8: 3 | K8: 4 | L8: 67 | M8: 44 | N8: 3 | O8: 3.33
A9: 04-Jan-2025 | B9: W01 | C9: LinkedIn | D9: Educational | E9: Digital wallet security tips | F9: 1598 | G9: 1967 | H9: 43 | I9: 7 | J9: 4 | K9: 9 | L9: 129 | M9: 23 | N9: 0 | O9: 3.97
A10: 04-Jan-2025 | B10: W01 | C10: Instagram | D10: Educational | E10: Digital wallet security tips | F10: 1948 | G10: 2805 | H10: 36 | I10: 8 | J10: 4 | K10: 4 | L10: 164 | M10: 111 | N10: 18 | O10: 3.12
A11: 04-Jan-2025 | B11: W01 | C11: TikTok | D11: Educational | E11: Understanding transaction fees | F11: 9879 | G11: 14663 | H11: 270 | I11: 43 | J11: 22 | K11: 55 | L11: 963 | M11: 578 | N11: 49 | O11: 4.62 | P11: Possible viral reach spike
A12: 05-Jan-2025 | B12: W01 | C12: Instagram | D12: Promotional | E12: Limited time sign-up bonus | F12: 1874 | G12: 2247 | H12: 12 | I12: 3 | J12: 2 | K12: 3 | L12: 164 | M12: 64 | N12: 2 | O12: 1.19 | P12: Low engagement, promo fatigue
A13: 05-Jan-2025 | B13: W01 | C13: Facebook | D13: Promotional | E13: New year new wallet offer | F13: 855 | G13: 1043 | H13: 3 | I13: 1 | J13: 0 | K13: 1 | L13: 70 | M13: 13 | N13: 4 | O13: 0.84 | P13: Low engagement, promo fatigue
A14: 06-Jan-2025 | B14: W01 | C14: TikTok | D14: Behind the Scenes | E14: The team behind your midnight transactions | F14: 9218 | G14: 13319 | H14: 385 | I14: 93 | J14: 48 | K14: 88 | L14: 701 | M14: 206 | N14: 9 | O14: 6.86 | P14: Possible viral reach spike
A15: 06-Jan-2025 | B15: W01 | C15: LinkedIn | D15: Educational | E15: Understanding transaction fees | F15: 903 | G15: 1092 | H15: 10 | I15: 1 | J15: 1 | K15: 2 | L15: 41 | M15: 19 | N15: 5 | O15: 1.96
A16: 06-Jan-2025 | B16: W01 | C16: Facebook | D16: Promotional | E16: Refer a friend get KSh 100 | F16: 1736 | G16: 2675 | H16: 8 | I16: 1 | J16: 1 | K16: 0 | L16: 160 | M16: 48 | N16: 3 | O16: 0.84 | P16: Low engagement, promo fatigue
A17: 07-Jan-2025 | B17: W01 | C17: Instagram | D17: Educational | E17: Digital wallet security tips | F17: 2877 | G17: 4404 | H17: 32 | I17: 6 | J17: 4 | K17: 4 | L17: 172 | M17: 161 | N17: 12 | O17: 1.96
A18: 07-Jan-2025 | B18: W01 | C18: Facebook | D18: Behind the Scenes | E18: The team behind your midnight transactions | F18: 1110 | G18: 1582 | H18: 8 | I18: 1 | J18: 1 | K18: 1 | L18: 80 | M18: 37 | N18: 11 | O18: 1.5
A19: 07-Jan-2025 | B19: W01 | C19: LinkedIn | D19: Behind the Scenes | E19: How we built the new savings feature | F19: 1128 | G19: 1796 | H19: 18 | I19: 3 | J19: 2 | K19: 4 | L19: 134 | M19: 42 | N19: 5 | O19: 2.53
A20: 08-Jan-2025 | B20: W02 | C20: Facebook | D20: Promotional | E20: Fagiafest offer, zero transfer fees | F20: 1474 | G20: 2020 | H20: 7 | I20: 1 | J20: 1 | K20: 1 | L20: 77 | M20: 85 | N20: 1 | O20: 1.01 | P20: Low engagement, promo fatigue
A21: 09-Jan-2025 | B21: W02 | C21: Instagram | D21: Product Feature | E21: Split payments feature launch | F21: 2523 | G21: 3963 | H21: 38 | I21: 5 | J21: 3 | K21: 6 | L21: 215 | M21: 65 | N21: 6 | O21: 2.38
A22: 10-Jan-2025 | B22: W02 | C22: Facebook | D22: Promotional | E22: Refer a friend get KSh 100 | F22: 1642 | G22: 2052 | H22: 5 | I22: 0 | J22: 0 | K22: 1 | L22: 196 | M22: 22 | N22: 2 | O22: 0.59 | P22: Low engagement, promo fatigue
A23: 10-Jan-2025 | B23: W02 | C23: Instagram | D23: Promotional | E23: New year new wallet offer | F23: 2841 | G23: 4374 | H23: 18 | I23: 5 | J23: 3 | K23: 3 | L23: 338 | M23: 121 | N23: 1 | O23: 1.18 | P23: Low engagement, promo fatigue
A24: 11-Jan-2025 | B24: W02 | C24: Facebook | D24: Behind the Scenes | E24: How we built the new savings feature | F24: 1673 | G24: 2584 | H24: 17 | I24: 3 | J24: 2 | K24: 2 | L24: 158 | M24: 88 | N24: 7 | O24: 1.87
A25: 11-Jan-2025 | B25: W02 | C25: LinkedIn | D25: Promotional | E25: Fagiafest offer, zero transfer fees | F25: 306 | G25: 401 | H25: 2 | I25: 0 | J25: 0 | K25: 0 | L25: 30 | M25: 11 | N25: 1 | O25: 1.38
A26: 11-Jan-2025 | B26: W02 | C26: Instagram | D26: Educational | E26: How M-PESA limits work | F26: 6015 | G26: 8694 | H26: 53 | I26: 11 | J26: 8 | K26: 9 | L26: 260 | M26: 169 | N26: 23 | O26: 1.62
A27: 12-Jan-2025 | B27: W02 | C27: Instagram | D27: Product Feature | E27: International transfers, step by step | F27: 1298 | G27: 1934 | H27: 25 | I27: 5 | J27: 2 | K27: 5 | L27: 141 | M27: 76 | N27: 16 | O27: 3.21
A28: 12-Jan-2025 | B28: W02 | C28: TikTok | D28: Behind the Scenes | E28: Meet our customer support team in Nairobi | F28: 3378 | G28: 5277 | H28: 151 | I28: 36 | J28: 25 | K28: 18 | L28: 178 | M28: 152 | N28: 26 | O28: 7.34
A29: 12-Jan-2025 | B29: W02 | C29: LinkedIn | D29: Educational | E29: Sending money abroad safely | F29: 887 | G29: 1337 | H29: 17 | I29: 4 | J29: 1 | K29: 1 | L29: 49 | M29: 23 | N29: 7 | O29: 3.48
A30: 13-Jan-2025 | B30: W02 | C30: Facebook | D30: Product Feature | E30: Business accounts, what's different | F30: 1607 | G30: 1789 | H30: 16 | I30: 3 | J30: 3 | K30: 1 | L30: 140 | M30: 43 | N30: 8 | O30: 1.79
A31: 13-Jan-2025 | B31: W02 | C31: TikTok | D31: UGC / Testimonial | E31: University student budgeting with PesaPal | F31: 3783 | G31: 5862 | H31: 94 | I31: 21 | J31: 14 | K31: 22 | L31: 359 | M31: 215 | N31: 62 | O31: 4.51 | P31: High performer, amplify this
A32: 13-Jan-2025 | B32: W02 | C32: LinkedIn | D32: Educational | E32: Sending money abroad safely | F32: 566 | G32: 810 | H32: 9 | I32: 2 | J32: 1 | K32: 1 | L32: 36 | M32: 17 | N32: 3 | O32: 2.97
A33: 14-Jan-2025 | B33: W02 | C33: TikTok | D33: Educational | E33: Digital wallet security tips | F33: 11948 | G33: 17189 | H33: 675 | I33: 115 | J33: 92 | K33: 52 | L33: 752 | M33: 376 | N33: 39 | O33: 8.8 | P33: Possible viral reach spike
A34: 15-Jan-2025 | B34: W03 | C34: LinkedIn | D34: UGC / Testimonial | E34: Mama mboga grows her business with PesaPal | F34: 1920 | G34: 2873 | H34: 88 | I34: 19 | J34: 9 | K34: 15 | L34: 171 | M34: 28 | N34: 10 | O34: 7 | P34: High performer, amplify this
A35: 15-Jan-2025 | B35: W03 | C35: TikTok | D35: Promotional | E35: New year new wallet offer | F35: 2066 | G35: 2478 | H35: 13 | I35: 2 | J35: 2 | K35: 1 | L35: 151 | M35: 85 | N35: 8 | O35: 1.14 | P35: Low engagement, promo fatigue
A36: 16-Jan-2025 | B36: W03 | C36: LinkedIn | D36: Promotional | E36: Limited time sign-up bonus | F36: 932 | G36: 1441 | H36: 15 | I36: 3 | J36: 1 | K36: 2 | L36: 89 | M36: 30 | N36: 2 | O36: 2.53
A37: 16-Jan-2025 | B37: W03 | C37: TikTok | D37: Behind the Scenes | E37: Meet our customer support team in Nairobi | F37: 6188 | G37: 9286 | H37: 282 | I37: 56 | J37: 47 | K37: 56 | L37: 550 | M37: 284 | N37: 32 | O37: 6.55 | P37: Possible viral reach spike
A38: 17-Jan-2025 | B38: W03 | C38: LinkedIn | D38: UGC / Testimonial | E38: Mama mboga grows her business with PesaPal | F38: 2807 | G38: 3476 | H38: 105 | I38: 17 | J38: 13 | K38: 20 | L38: 164 | M38: 75 | N38: 9 | O38: 6.08 | P38: High performer, amplify this
A39: 17-Jan-2025 | B39: W03 | C39: Instagram | D39: Educational | E39: What is a credit score? | F39: 2317 | G39: 3352 | H39: 44 | I39: 9 | J39: 7 | K39: 7 | L39: 131 | M39: 71 | N39: 23 | O39: 3.49
A40: 17-Jan-2025 | B40: W03 | C40: TikTok | D40: Product Feature | E40: International transfers, step by step | F40: 1487 | G40: 2290 | H40: 45 | I40: 12 | J40: 5 | K40: 6 | L40: 165 | M40: 77 | N40: 29 | O40: 5.01
...

Sheet Summary Dashboard
A1: PesaPal Kenya - 90-Day Social Media Performance Dashboard
A2: Period: 1 January 2025 – 31 March 2025 | Platforms: Instagram, TikTok, Facebook, LinkedIn | Brand: PesaPal Kenya
A4: SECTION 1 - OVERALL CAMPAIGN KPIs (All Platforms Combined)
A5: Metric | B5: Value | D5: Metric | E5: Value
A6: Total Posts Published | B6: =COUNTA('Raw Data'!A3:A179) -> 177 | D6: Total Reach | E6: =SUM('Raw Data'!F3:F179) -> 568466
A7: Total Impressions | B7: =SUM('Raw Data'!G3:G179) -> 781707 | D7: Total Likes | E7: =SUM('Raw Data'!H3:H179) -> 14304
A8: Total Comments | B8: =SUM('Raw Data'!I3:I179) -> 2984 | D8: Total Shares | E8: =SUM('Raw Data'!J3:J179) -> 1854
A9: Total Saves | B9: =SUM('Raw Data'!K3:K179) -> 2282 | D9: Total Link Clicks | E9: =SUM('Raw Data'!M3:M179) -> 20379
A10: Total New Followers | B10: =SUM('Raw Data'!N3:N179) -> 2419 | D10: Avg Engagement Rate | E10: =AVERAGE('Raw Data'!O3:O179) -> 3.1314689
A12: SECTION 2 - PLATFORM BREAKDOWN
A13: Platform | B13: Posts | C13: Avg Reach | D13: Avg Eng Rate (%) | E13: Total Followers | F13: Best Content Type
A14: Instagram | B14: =COUNTIF('Raw Data'!C3:C179,"Instagram") -> 45 | C14: =AVERAGEIF('Raw Data'!C3:C179,"Instagram",'Raw Data'!F3:F179) -> 3105.6222 | D14: =AVERAGEIF('Raw Data'!C3:C179,"Instagram",'Raw Data'!O3:O179) -> 2.3782222 | E14: =SUMIF('Raw Data'!C3:C179,"Instagram",'Raw Data'!N3:N179) -> 570 | F14: UGC / Testimonial
A15: TikTok | B15: =COUNTIF('Raw Data'!C3:C179,"TikTok") -> 45 | C15: =AVERAGEIF('Raw Data'!C3:C179,"TikTok",'Raw Data'!F3:F179) -> 6229.5778 | D15: =AVERAGEIF('Raw Data'!C3:C179,"TikTok",'Raw Data'!O3:O179) -> 5.206 | E15: =SUMIF('Raw Data'!C3:C179,"TikTok",'Raw Data'!N3:N179) -> 1400 | F15: Community / Cultural
A16: Facebook | B16: =COUNTIF('Raw Data'!C3:C179,"Facebook") -> 41 | C16: =AVERAGEIF('Raw Data'!C3:C179,"Facebook",'Raw Data'!F3:F179) -> 2185.6585 | D16: =AVERAGEIF('Raw Data'!C3:C179,"Facebook",'Raw Data'!O3:O179) -> 1.4429268 | E16: =SUMIF('Raw Data'!C3:C179,"Facebook",'Raw Data'!N3:N179) -> 288 | F16: Educational
A17: LinkedIn | B17: =COUNTIF('Raw Data'!C3:C179,"LinkedIn") -> 46 | C17: =AVERAGEIF('Raw Data'!C3:C179,"LinkedIn",'Raw Data'!F3:F179) -> 1277.6087 | D17: =AVERAGEIF('Raw Data'!C3:C179,"LinkedIn",'Raw Data'!O3:O179) -> 3.343913 | E17: =SUMIF('Raw Data'!C3:C179,"LinkedIn",'Raw Data'!N3:N179) -> 161 | F17: Product Feature
A20: SECTION 3 - CONTENT TYPE PERFORMANCE
A21: Content Type | B21: Posts | C21: Avg Reach | D21: Avg Eng Rate (%) | E21: Avg Followers Gained | F21: Assessment
A22: Educational | B22: =COUNTIF('Raw Data'!D3:D179,"Educational") -> 40 | C22: =AVERAGEIF('Raw Data'!D3:D179,"Educational",'Raw Data'!F3:F179) -> 3916.975 | D22: =AVERAGEIF('Raw Data'!D3:D179,"Educational",'Raw Data'!O3:O179) -> 3.8005 | E22: =AVERAGEIF('Raw Data'!D3:D179,"Educational",'Raw Data'!N3:N179) -> 16.525 | F22: Consistent performer, high save rate
A23: Promotional | B23: =COUNTIF('Raw Data'!D3:D179,"Promotional") -> 37 | C23: =AVERAGEIF('Raw Data'!D3:D179,"Promotional",'Raw Data'!F3:F179) -> 1780.5405 | D23: =AVERAGEIF('Raw Data'!D3:D179,"Promotional",'Raw Data'!O3:O179) -> 1.5597297 | E23: =AVERAGEIF('Raw Data'!D3:D179,"Promotional",'Raw Data'!N3:N179) -> 5.7567568 | F23: Lowest engagement, reduce frequency
A24: UGC / Testimonial | B24: =COUNTIF('Raw Data'!D3:D179,"UGC / Testimonial") -> 21 | C24: =AVERAGEIF('Raw Data'!D3:D179,"UGC / Testimonial",'Raw Data'!F3:F179) -> 4671 | D24: =AVERAGEIF('Raw Data'!D3:D179,"UGC / Testimonial",'Raw Data'!O3:O179) -> 4.157619 | E24: =AVERAGEIF('Raw Data'!D3:D179,"UGC / Testimonial",'Raw Data'!N3:N179) -> 20.952381 | F24: Top performer, scale this format
A25: Product Feature | B25: =COUNTIF('Raw Data'!D3:D179,"Product Feature") -> 33 | C25: =AVERAGEIF('Raw Data'!D3:D179,"Product Feature",'Raw Data'!F3:F179) -> 2489.0303 | D25: =AVERAGEIF('Raw Data'!D3:D179,"Product Feature",'Raw Data'!O3:O179) -> 2.6660606 | E25: =AVERAGEIF('Raw Data'!D3:D179,"Product Feature",'Raw Data'!N3:N179) -> 12.787879 | F25: Mid-tier, improve with demos
A26: Community / Cultural | B26: =COUNTIF('Raw Data'!D3:D179,"Community / Cultural") -> 19 | C26: =AVERAGEIF('Raw Data'!D3:D179,"Community / Cultural",'Raw Data'!F3:F179) -> 4352.7368 | D26: =AVERAGEIF('Raw Data'!D3:D179,"Community / Cultural",'Raw Data'!O3:O179) -> 3.9110526 | E26: =AVERAGEIF('Raw Data'!D3:D179,"Community / Cultural",'Raw Data'!N3:N179) -> 16.578947 | F26: Strong reach, culturally resonant
A27: Behind the Scenes | B27: =COUNTIF('Raw Data'!D3:D179,"Behind the Scenes") -> 27 | C27: =AVERAGEIF('Raw Data'!D3:D179,"Behind the Scenes",'Raw Data'!F3:F179) -> 3073.1852 | D27: =AVERAGEIF('Raw Data'!D3:D179,"Behind the Scenes",'Raw Data'!O3:O179) -> 3.5162963 | E27: =AVERAGEIF('Raw Data'!D3:D179,"Behind the Scenes",'Raw Data'!N3:N179) -> 13.62963 | F27: Underused but high engagement when posted
A30: SECTION 4 - WEEKLY TREND (Total Reach by Week)
A31: Week | B31: Total Reach | C31: Total Posts | D31: Avg Eng Rate (%) | E31: New Followers | F31: Trend Note
A32: W01 | B32: =SUMIF('Raw Data'!B3:B179,"W01",'Raw Data'!F3:F179) -> 45486 | C32: =COUNTIF('Raw Data'!B3:B179,"W01") -> 17 | D32: =AVERAGEIF('Raw Data'!B3:B179,"W01",'Raw Data'!O3:O179) -> 2.8058824 | E32: =SUMIF('Raw Data'!B3:B179,"W01",'Raw Data'!N3:N179) -> 182 | F32: Baseline week, low posting volume
A33: W02 | B33: =SUMIF('Raw Data'!B3:B179,"W02",'Raw Data'!F3:F179) -> 39941 | C33: =COUNTIF('Raw Data'!B3:B179,"W02") -> 14 | D33: =AVERAGEIF('Raw Data'!B3:B179,"W02",'Raw Data'!O3:O179) -> 3.0092857 | E33: =SUMIF('Raw Data'!B3:B179,"W02",'Raw Data'!N3:N179) -> 202 | F33: UGC campaign launched, reach spike
A34: W03 | B34: =SUMIF('Raw Data'!B3:B179,"W03",'Raw Data'!F3:F179) -> 49227 | C34: =COUNTIF('Raw Data'!B3:B179,"W03") -> 16 | D34: =AVERAGEIF('Raw Data'!B3:B179,"W03",'Raw Data'!O3:O179) -> 4.13375 | E34: =SUMIF('Raw Data'!B3:B179,"W03",'Raw Data'!N3:N179) -> 268 | F34: Consistent output
A35: W04 | B35: =SUMIF('Raw Data'!B3:B179,"W04",'Raw Data'!F3:F179) -> 37111 | C35: =COUNTIF('Raw Data'!B3:B179,"W04") -> 13 | D35: =AVERAGEIF('Raw Data'!B3:B179,"W04",'Raw Data'!O3:O179) -> 2.9607692 | E35: =SUMIF('Raw Data'!B3:B179,"W04",'Raw Data'!N3:N179) -> 139 | F35: Promotional push, lower engagement
A36: W05 | B36: =SUMIF('Raw Data'!B3:B179,"W05",'Raw Data'!F3:F179) -> 84045 | C36: =COUNTIF('Raw Data'!B3:B179,"W05") -> 16 | D36: =AVERAGEIF('Raw Data'!B3:B179,"W05",'Raw Data'!O3:O179) -> 3.55125 | E36: =SUMIF('Raw Data'!B3:B179,"W05",'Raw Data'!N3:N179) -> 287 | F36: Valentine's campaign, community surge
A37: W06 | B37: =SUMIF('Raw Data'!B3:B179,"W06",'Raw Data'!F3:F179) -> 43939 | C37: =COUNTIF('Raw Data'!B3:B179,"W06") -> 13 | D37: =AVERAGEIF('Raw Data'!B3:B179,"W06",'Raw Data'!O3:O179) -> 3.3876923 | E37: =SUMIF('Raw Data'!B3:B179,"W06",'Raw Data'!N3:N179) -> 217 | F37: TikTok viral post, outlier week
A38: W07 | B38: =SUMIF('Raw Data'!B3:B179,"W07",'Raw Data'!F3:F179) -> 36555 | C38: =COUNTIF('Raw Data'!B3:B179,"W07") -> 13 | D38: =AVERAGEIF('Raw Data'!B3:B179,"W07",'Raw Data'!O3:O179) -> 3.0269231 | E38: =SUMIF('Raw Data'!B3:B179,"W07",'Raw Data'!N3:N179) -> 138 | F38: Stable, behind the scenes series
A39: W08 | B39: =SUMIF('Raw Data'!B3:B179,"W08",'Raw Data'!F3:F179) -> 32265 | C39: =COUNTIF('Raw Data'!B3:B179,"W08") -> 13 | D39: =AVERAGEIF('Raw Data'!B3:B179,"W08",'Raw Data'!O3:O179) -> 2.6161538 | E39: =SUMIF('Raw Data'!B3:B179,"W08",'Raw Data'!N3:N179) -> 177 | F39: Educational series high saves
A40: W09 | B40: =SUMIF('Raw Data'!B3:B179,"W09",'Raw Data'!F3:F179) -> 39650 | C40: =COUNTIF('Raw Data'!B3:B179,"W09") -> 13 | D40: =AVERAGEIF('Raw Data'!B3:B179,"W09",'Raw Data'!O3:O179) -> 2.6407692 | E40: =SUMIF('Raw Data'!B3:B179,"W09",'Raw Data'!N3:N179) -> 192 | F40: End of quarter, all-platform push
A41: W10 | B41: =SUMIF('Raw Data'!B3:B179,"W10",'Raw Data'!F3:F179) -> 27821 | C41: =COUNTIF('Raw Data'!B3:B179,"W10") -> 11 | D41: =AVERAGEIF('Raw Data'!B3:B179,"W10",'Raw Data'!O3:O179) -> 3.1172727 | E41: =SUMIF('Raw Data'!B3:B179,"W10",'Raw Data'!N3:N179) -> 110 | F41: Final week, follower growth strong
A42: W11 | B42: =SUMIF('Raw Data'!B3:B179,"W11",'Raw Data'!F3:F179) -> 56412 | C42: =COUNTIF('Raw Data'!B3:B179,"W11") -> 15 | D42: =AVERAGEIF('Raw Data'!B3:B179,"W11",'Raw Data'!O3:O179) -> 3.3686667 | E42: =SUMIF('Raw Data'!B3:B179,"W11",'Raw Data'!N3:N179) -> 256 | F42: Easter, cultural content peaks
A43: W12 | B43: =SUMIF('Raw Data'!B3:B179,"W12",'Raw Data'!F3:F179) -> 40512 | C43: =COUNTIF('Raw Data'!B3:B179,"W12") -> 13 | D43: =AVERAGEIF('Raw Data'!B3:B179,"W12",'Raw Data'!O3:O179) -> 2.7392308 | E43: =SUMIF('Raw Data'!B3:B179,"W12",'Raw Data'!N3:N179) -> 118 | F43: Quarter close, summary push
A44: W13 | B44: =SUMIF('Raw Data'!B3:B179,"W13",'Raw Data'!F3:F179) -> 35502 | C44: =COUNTIF('Raw Data'!B3:B179,"W13") -> 10 | D44: =AVERAGEIF('Raw Data'!B3:B179,"W13",'Raw Data'!O3:O179) -> 3.083 | E44: =SUMIF('Raw Data'!B3:B179,"W13",'Raw Data'!N3:N179) -> 133 | F44: Q1 wrap, engagement consolidates
A47: KEY FINDINGS & RECOMMENDATIONS
A48: Finding 1 | B48: UGC / Testimonial content drives highest engagement across ALL platforms, prioritise this format (target: 25% of monthly content mix).
...
